Traceback (most recent call last):
  File "/Users/nicolekeeney/opt/anaconda3/envs/is2-book-env/lib/python3.7/site-packages/jupyter_cache/executors/utils.py", line 56, in single_nb_execution
    record_timing=False,
  File "/Users/nicolekeeney/opt/anaconda3/envs/is2-book-env/lib/python3.7/site-packages/nbclient/client.py", line 1082, in execute
    return NotebookClient(nb=nb, resources=resources, km=km, **kwargs).execute()
  File "/Users/nicolekeeney/opt/anaconda3/envs/is2-book-env/lib/python3.7/site-packages/nbclient/util.py", line 74, in wrapped
    return just_run(coro(*args, **kwargs))
  File "/Users/nicolekeeney/opt/anaconda3/envs/is2-book-env/lib/python3.7/site-packages/nbclient/util.py", line 53, in just_run
    return loop.run_until_complete(coro)
  File "/Users/nicolekeeney/opt/anaconda3/envs/is2-book-env/lib/python3.7/asyncio/base_events.py", line 587, in run_until_complete
    return future.result()
  File "/Users/nicolekeeney/opt/anaconda3/envs/is2-book-env/lib/python3.7/site-packages/nbclient/client.py", line 536, in async_execute
    cell, index, execution_count=self.code_cells_executed + 1
  File "/Users/nicolekeeney/opt/anaconda3/envs/is2-book-env/lib/python3.7/site-packages/nbclient/client.py", line 827, in async_execute_cell
    self._check_raise_for_error(cell, exec_reply)
  File "/Users/nicolekeeney/opt/anaconda3/envs/is2-book-env/lib/python3.7/site-packages/nbclient/client.py", line 735, in _check_raise_for_error
    raise CellExecutionError.from_cell_and_msg(cell, exec_reply['content'])
nbclient.exceptions.CellExecutionError: An error occurred while executing the following cell:
------------------
#drop projection variable 
is2 = is2.drop('projection')

#get lat and lon
is2Lats = is2.latitude.isel(time = 0).values
is2Lons = is2.longitude.isel(time = 0).values
is2LonsAttrs = is2.longitude.attrs 
is2LatsAttrs = is2.latitude.attrs

#assign lat and lon as coordinates to dataset
is2 = is2.assign_coords(coords = {'latitude': (('x','y'), is2Lats), 'longitude': (('x','y'), is2Lons)})
------------------

[0;31m---------------------------------------------------------------------------[0m
[0;31mAttributeError[0m                            Traceback (most recent call last)
[0;32m<ipython-input-7-3999d6296113>[0m in [0;36m<module>[0;34m[0m
[1;32m      1[0m [0;31m#drop projection variable[0m[0;34m[0m[0;34m[0m[0;34m[0m[0m
[0;32m----> 2[0;31m [0mis2[0m [0;34m=[0m [0mis2[0m[0;34m.[0m[0mdrop[0m[0;34m([0m[0;34m'projection'[0m[0;34m)[0m[0;34m[0m[0;34m[0m[0m
[0m[1;32m      3[0m [0;34m[0m[0m
[1;32m      4[0m [0;31m#get lat and lon[0m[0;34m[0m[0;34m[0m[0;34m[0m[0m
[1;32m      5[0m [0mis2Lats[0m [0;34m=[0m [0mis2[0m[0;34m.[0m[0mlatitude[0m[0;34m.[0m[0misel[0m[0;34m([0m[0mtime[0m [0;34m=[0m [0;36m0[0m[0;34m)[0m[0;34m.[0m[0mvalues[0m[0;34m[0m[0;34m[0m[0m

[0;31mAttributeError[0m: 'NoneType' object has no attribute 'drop'
AttributeError: 'NoneType' object has no attribute 'drop'

