Traceback (most recent call last):
  File "/Users/nicolekeeney/opt/anaconda3/envs/icesat2_book/lib/python3.8/site-packages/jupyter_cache/executors/utils.py", line 51, in single_nb_execution
    executenb(
  File "/Users/nicolekeeney/opt/anaconda3/envs/icesat2_book/lib/python3.8/site-packages/nbclient/client.py", line 1117, in execute
    return NotebookClient(nb=nb, resources=resources, km=km, **kwargs).execute()
  File "/Users/nicolekeeney/opt/anaconda3/envs/icesat2_book/lib/python3.8/site-packages/nbclient/util.py", line 78, in wrapped
    return just_run(coro(*args, **kwargs))
  File "/Users/nicolekeeney/opt/anaconda3/envs/icesat2_book/lib/python3.8/site-packages/nbclient/util.py", line 57, in just_run
    return loop.run_until_complete(coro)
  File "/Users/nicolekeeney/opt/anaconda3/envs/icesat2_book/lib/python3.8/asyncio/base_events.py", line 616, in run_until_complete
    return future.result()
  File "/Users/nicolekeeney/opt/anaconda3/envs/icesat2_book/lib/python3.8/site-packages/nbclient/client.py", line 558, in async_execute
    await self.async_execute_cell(
  File "/Users/nicolekeeney/opt/anaconda3/envs/icesat2_book/lib/python3.8/site-packages/nbclient/client.py", line 862, in async_execute_cell
    self._check_raise_for_error(cell, exec_reply)
  File "/Users/nicolekeeney/opt/anaconda3/envs/icesat2_book/lib/python3.8/site-packages/nbclient/client.py", line 765, in _check_raise_for_error
    raise CellExecutionError.from_cell_and_msg(cell, exec_reply_content)
nbclient.exceptions.CellExecutionError: An error occurred while executing the following cell:
------------------
regions = pd.DataFrame({"labels":ds.region_mask.attrs["labels"]}, index=ds.region_mask.attrs["keys"])
print(regions)
------------------

[0;31m---------------------------------------------------------------------------[0m
[0;31mAttributeError[0m                            Traceback (most recent call last)
[0;32m/var/folders/8v/cr06mz0n3bjd5jr12_9v6n200000gn/T/ipykernel_81929/1017187880.py[0m in [0;36m<module>[0;34m[0m
[0;32m----> 1[0;31m [0mregions[0m [0;34m=[0m [0mpd[0m[0;34m.[0m[0mDataFrame[0m[0;34m([0m[0;34m{[0m[0;34m"labels"[0m[0;34m:[0m[0mds[0m[0;34m.[0m[0mregion_mask[0m[0;34m.[0m[0mattrs[0m[0;34m[[0m[0;34m"labels"[0m[0;34m][0m[0;34m}[0m[0;34m,[0m [0mindex[0m[0;34m=[0m[0mds[0m[0;34m.[0m[0mregion_mask[0m[0;34m.[0m[0mattrs[0m[0;34m[[0m[0;34m"keys"[0m[0;34m][0m[0;34m)[0m[0;34m[0m[0;34m[0m[0m
[0m[1;32m      2[0m [0mprint[0m[0;34m([0m[0mregions[0m[0;34m)[0m[0;34m[0m[0;34m[0m[0m

[0;32m~/opt/anaconda3/envs/icesat2_book/lib/python3.8/site-packages/xarray/core/common.py[0m in [0;36m__getattr__[0;34m(self, name)[0m
[1;32m    237[0m                 [0;32mwith[0m [0msuppress[0m[0;34m([0m[0mKeyError[0m[0;34m)[0m[0;34m:[0m[0;34m[0m[0;34m[0m[0m
[1;32m    238[0m                     [0;32mreturn[0m [0msource[0m[0;34m[[0m[0mname[0m[0;34m][0m[0;34m[0m[0;34m[0m[0m
[0;32m--> 239[0;31m         raise AttributeError(
[0m[1;32m    240[0m             [0;34m"{!r} object has no attribute {!r}"[0m[0;34m.[0m[0mformat[0m[0;34m([0m[0mtype[0m[0;34m([0m[0mself[0m[0;34m)[0m[0;34m.[0m[0m__name__[0m[0;34m,[0m [0mname[0m[0;34m)[0m[0;34m[0m[0;34m[0m[0m
[1;32m    241[0m         )

[0;31mAttributeError[0m: 'Dataset' object has no attribute 'region_mask'
AttributeError: 'Dataset' object has no attribute 'region_mask'

