Traceback (most recent call last):
  File "/Users/nicolekeeney/opt/anaconda3/envs/icesat2_book/lib/python3.8/site-packages/nbclient/client.py", line 622, in _async_poll_for_reply
    msg = await ensure_async(self.kc.shell_channel.get_msg(timeout=new_timeout))
  File "/Users/nicolekeeney/opt/anaconda3/envs/icesat2_book/lib/python3.8/site-packages/nbclient/util.py", line 85, in ensure_async
    result = await obj
  File "/Users/nicolekeeney/opt/anaconda3/envs/icesat2_book/lib/python3.8/site-packages/jupyter_client/asynchronous/channels.py", line 48, in get_msg
    raise Empty
_queue.Empty

During handling of the above exception, another exception occurred:

Traceback (most recent call last):
  File "/Users/nicolekeeney/opt/anaconda3/envs/icesat2_book/lib/python3.8/site-packages/jupyter_cache/executors/utils.py", line 51, in single_nb_execution
    executenb(
  File "/Users/nicolekeeney/opt/anaconda3/envs/icesat2_book/lib/python3.8/site-packages/nbclient/client.py", line 1112, in execute
    return NotebookClient(nb=nb, resources=resources, km=km, **kwargs).execute()
  File "/Users/nicolekeeney/opt/anaconda3/envs/icesat2_book/lib/python3.8/site-packages/nbclient/util.py", line 74, in wrapped
    return just_run(coro(*args, **kwargs))
  File "/Users/nicolekeeney/opt/anaconda3/envs/icesat2_book/lib/python3.8/site-packages/nbclient/util.py", line 53, in just_run
    return loop.run_until_complete(coro)
  File "/Users/nicolekeeney/opt/anaconda3/envs/icesat2_book/lib/python3.8/asyncio/base_events.py", line 616, in run_until_complete
    return future.result()
  File "/Users/nicolekeeney/opt/anaconda3/envs/icesat2_book/lib/python3.8/site-packages/nbclient/client.py", line 553, in async_execute
    await self.async_execute_cell(
  File "/Users/nicolekeeney/opt/anaconda3/envs/icesat2_book/lib/python3.8/site-packages/nbclient/client.py", line 841, in async_execute_cell
    exec_reply = await self.task_poll_for_reply
  File "/Users/nicolekeeney/opt/anaconda3/envs/icesat2_book/lib/python3.8/site-packages/nbclient/client.py", line 646, in _async_poll_for_reply
    await self._async_handle_timeout(timeout, cell)
  File "/Users/nicolekeeney/opt/anaconda3/envs/icesat2_book/lib/python3.8/site-packages/nbclient/client.py", line 696, in _async_handle_timeout
    raise CellTimeoutError.error_from_timeout_and_cell(
nbclient.exceptions.CellTimeoutError: A cell timed out while it was being executed, after 30 seconds.
The message was: Cell execution timed out.
Here is a preview of the cell contents:
-------------------
['# Set desired date range ', 'winter18_19 = pd.date_range(start="2018-11-01", end="2019-04-01", freq="MS")', 'winter19_20 = pd.date_range(start="2019-09-01", end="2020-04-01", freq="MS")', 'winter20_21 = pd.date_range(start="2020-09-01", end="2020-12-01", freq="MS") # We don\'t have data for 2021 yet for several of the datasets', 'winter_months = winter18_19.append(winter19_20).append(winter20_21)']
...
['    print("Complete!")', '    ', '# Combine datasets ', 'ds = xr.merge([is2_ds, book_ds])', 'ds = ds.drop_vars("projection")']
-------------------

