Traceback (most recent call last):
  File "/Users/akpetty/miniconda3/envs/is2book_p39_env/lib/python3.9/site-packages/jupyter_cache/executors/utils.py", line 58, in single_nb_execution
    executenb(
  File "/Users/akpetty/miniconda3/envs/is2book_p39_env/lib/python3.9/site-packages/nbclient/client.py", line 1305, in execute
    return NotebookClient(nb=nb, resources=resources, km=km, **kwargs).execute()
  File "/Users/akpetty/miniconda3/envs/is2book_p39_env/lib/python3.9/site-packages/jupyter_core/utils/__init__.py", line 166, in wrapped
    return loop.run_until_complete(inner)
  File "/Users/akpetty/miniconda3/envs/is2book_p39_env/lib/python3.9/asyncio/base_events.py", line 647, in run_until_complete
    return future.result()
  File "/Users/akpetty/miniconda3/envs/is2book_p39_env/lib/python3.9/site-packages/nbclient/client.py", line 705, in async_execute
    await self.async_execute_cell(
  File "/Users/akpetty/miniconda3/envs/is2book_p39_env/lib/python3.9/site-packages/nbclient/client.py", line 1058, in async_execute_cell
    await self._check_raise_for_error(cell, cell_index, exec_reply)
  File "/Users/akpetty/miniconda3/envs/is2book_p39_env/lib/python3.9/site-packages/nbclient/client.py", line 914, in _check_raise_for_error
    raise CellExecutionError.from_cell_and_msg(cell, exec_reply_content)
nbclient.exceptions.CellExecutionError: An error occurred while executing the following cell:
------------------
IS2SITMOGR4_v3 = read_IS2SITMOGR4(data_type='zarr-s3', 
                                   local_data_path='./data/IS2SITMOGR4/', version='V3', 
                                  download=False, persist=True) 

IS2SITMOGR4_v3
------------------


[0;31m---------------------------------------------------------------------------[0m
[0;31mTypeError[0m                                 Traceback (most recent call last)
Cell [0;32mIn[2], line 1[0m
[0;32m----> 1[0m IS2SITMOGR4_v3 [38;5;241m=[39m [43mread_IS2SITMOGR4[49m[43m([49m[43mdata_type[49m[38;5;241;43m=[39;49m[38;5;124;43m'[39;49m[38;5;124;43mzarr-s3[39;49m[38;5;124;43m'[39;49m[43m,[49m[43m [49m
[1;32m      2[0m [43m                                   [49m[43mlocal_data_path[49m[38;5;241;43m=[39;49m[38;5;124;43m'[39;49m[38;5;124;43m./data/IS2SITMOGR4/[39;49m[38;5;124;43m'[39;49m[43m,[49m[43m [49m[43mversion[49m[38;5;241;43m=[39;49m[38;5;124;43m'[39;49m[38;5;124;43mV3[39;49m[38;5;124;43m'[39;49m[43m,[49m[43m [49m
[1;32m      3[0m [43m                                  [49m[43mdownload[49m[38;5;241;43m=[39;49m[38;5;28;43;01mFalse[39;49;00m[43m,[49m[43m [49m[43mpersist[49m[38;5;241;43m=[39;49m[38;5;28;43;01mTrue[39;49;00m[43m)[49m 
[1;32m      5[0m IS2SITMOGR4_v3

[0;31mTypeError[0m: read_IS2SITMOGR4() got an unexpected keyword argument 'download'

